conformant = "Unsupported"
notes = """
Does not understand Unpack in the context of **kwargs annotation.
"""
output = """
File "callables_kwargs.py", line 10, in <module>: typing.Unpack not supported yet [not-supported-yet]
File "callables_kwargs.py", line 24, in func1: Unpack[TD2] [assert-type]
File "callables_kwargs.py", line 30, in func1: Unpack[TD2] [assert-type]
File "callables_kwargs.py", line 33, in func1: Unpack[TD2] [assert-type]
File "callables_kwargs.py", line 39, in func2: Dict[str, Unpack[TD1]] [assert-type]
File "callables_kwargs.py", line 44, in func3: Function func1 was called with the wrong arguments [wrong-arg-types]
File "callables_kwargs.py", line 46, in func3: Missing parameter 'v2' in call to function TD2.__init__ [missing-parameter]
File "callables_kwargs.py", line 48, in func3: Function func1 was called with the wrong arguments [wrong-arg-types]
File "callables_kwargs.py", line 49, in func3: Function func1 expects 0 arg(s), got 3 [wrong-arg-count]
File "callables_kwargs.py", line 55, in func3: Function func1 was called with the wrong arguments [wrong-arg-types]
File "callables_kwargs.py", line 58, in func3: Function func1 was called with the wrong arguments [wrong-arg-types]
File "callables_kwargs.py", line 60, in func3: Function func1 was called with the wrong arguments [wrong-arg-types]
File "callables_kwargs.py", line 61, in func3: Function func2 was called with the wrong arguments [wrong-arg-types]
File "callables_kwargs.py", line 62, in func3: Function func2 was called with the wrong arguments [wrong-arg-types]
"""
conformance_automated = "Fail"
errors_diff = """
Line 26: Expected 1 errors
Line 43: Expected 1 errors
Line 98: Expected 1 errors
Line 99: Expected 1 errors
Line 100: Expected 1 errors
Line 108: Expected 1 errors
Line 120: Expected 1 errors
Line 10: Unexpected errors ['File "callables_kwargs.py", line 10, in <module>: typing.Unpack not supported yet [not-supported-yet]']
Line 24: Unexpected errors ['File "callables_kwargs.py", line 24, in func1: Unpack[TD2] [assert-type]']
Line 30: Unexpected errors ['File "callables_kwargs.py", line 30, in func1: Unpack[TD2] [assert-type]']
Line 33: Unexpected errors ['File "callables_kwargs.py", line 33, in func1: Unpack[TD2] [assert-type]']
Line 39: Unexpected errors ['File "callables_kwargs.py", line 39, in func2: Dict[str, Unpack[TD1]] [assert-type]']
Line 44: Unexpected errors ['File "callables_kwargs.py", line 44, in func3: Function func1 was called with the wrong arguments [wrong-arg-types]']
Line 46: Unexpected errors ['File "callables_kwargs.py", line 46, in func3: Missing parameter \\'v2\\' in call to function TD2.__init__ [missing-parameter]']
Line 58: Unexpected errors ['File "callables_kwargs.py", line 58, in func3: Function func1 was called with the wrong arguments [wrong-arg-types]']
"""
