conformant = "Unsupported"
notes = """
Does not understand `Self` type.
"""
output = """
File "generics_self_basic.py", line 13, in set_scale: Shape [assert-type]
File "generics_self_basic.py", line 13, in set_scale: Circle [assert-type]
Called from (traceback):
  line 51, in current file
File "generics_self_basic.py", line 26, in from_config: Type[Shape] [assert-type]
Called from (traceback):
  line 53, in current file
File "generics_self_basic.py", line 26, in from_config: Type[Circle] [assert-type]
Called from (traceback):
  line 54, in current file
File "generics_self_basic.py", line 27, in from_config: Function Shape.__init__ expects 1 arg(s), got 2 [wrong-arg-count]
Called from (traceback):
  line 53, in current file
File "generics_self_basic.py", line 27, in from_config: Function Circle.__init__ expects 1 arg(s), got 2 [wrong-arg-count]
Called from (traceback):
  line 54, in current file
File "generics_self_basic.py", line 39, in difference: Shape [assert-type]
File "generics_self_basic.py", line 61, in set_value: bad return type [bad-return-type]
Called from (traceback):
  line 72, in object_with_concrete_type
File "generics_self_basic.py", line 61, in set_value: bad return type [bad-return-type]
Called from (traceback):
  line 71, in object_with_concrete_type
File "generics_self_basic.py", line 61, in set_value: bad return type [bad-return-type]
File "generics_self_basic.py", line 64, in Container: unsupported operand type(s) for item retrieval: 'Self: TypeVar' and 'int: Type[int]' [unsupported-operands]
"""
conformance_automated = "Fail"
errors_diff = """
Line 13: Unexpected errors ['File "generics_self_basic.py", line 13, in set_scale: Shape [assert-type]', 'File "generics_self_basic.py", line 13, in set_scale: Circle [assert-type]']
Line 26: Unexpected errors ['File "generics_self_basic.py", line 26, in from_config: Type[Shape] [assert-type]', 'File "generics_self_basic.py", line 26, in from_config: Type[Circle] [assert-type]']
Line 27: Unexpected errors ['File "generics_self_basic.py", line 27, in from_config: Function Shape.__init__ expects 1 arg(s), got 2 [wrong-arg-count]', 'File "generics_self_basic.py", line 27, in from_config: Function Circle.__init__ expects 1 arg(s), got 2 [wrong-arg-count]']
Line 39: Unexpected errors ['File "generics_self_basic.py", line 39, in difference: Shape [assert-type]']
Line 61: Unexpected errors ['File "generics_self_basic.py", line 61, in set_value: bad return type [bad-return-type]', 'File "generics_self_basic.py", line 61, in set_value: bad return type [bad-return-type]', 'File "generics_self_basic.py", line 61, in set_value: bad return type [bad-return-type]']
Line 64: Unexpected errors ['File "generics_self_basic.py", line 64, in Container: unsupported operand type(s) for item retrieval: \\'Self: TypeVar\\' and \\'int: Type[int]\\' [unsupported-operands]']
"""
